[2023-10-17T02:49:57.708+0000] {taskinstance.py:1103} INFO - Dependencies all met for dep_context=non-requeueable deps ti=<TaskInstance: my_dag.accurate scheduled__2023-10-16T00:00:00+00:00 [queued]>
[2023-10-17T02:49:57.766+0000] {taskinstance.py:1103} INFO - Dependencies all met for dep_context=requeueable deps ti=<TaskInstance: my_dag.accurate scheduled__2023-10-16T00:00:00+00:00 [queued]>
[2023-10-17T02:49:57.772+0000] {taskinstance.py:1308} INFO - Starting attempt 1 of 1
[2023-10-17T02:49:58.057+0000] {taskinstance.py:1327} INFO - Executing <Task(BashOperator): accurate> on 2023-10-16 00:00:00+00:00
[2023-10-17T02:49:58.081+0000] {standard_task_runner.py:57} INFO - Started process 106 to run task
[2023-10-17T02:49:58.105+0000] {standard_task_runner.py:84} INFO - Running: ['***', 'tasks', 'run', 'my_dag', 'accurate', 'scheduled__2023-10-16T00:00:00+00:00', '--job-id', '117', '--raw', '--subdir', 'DAGS_FOLDER/my_dag.py', '--cfg-path', '/tmp/tmp1db9hekc']
[2023-10-17T02:49:58.364+0000] {standard_task_runner.py:85} INFO - Job 117: Subtask accurate
[2023-10-17T02:49:59.144+0000] {task_command.py:410} INFO - Running <TaskInstance: my_dag.accurate scheduled__2023-10-16T00:00:00+00:00 [running]> on host b9f7eb4d6527
[2023-10-17T02:50:00.125+0000] {taskinstance.py:1547} INFO - Exporting env vars: AIRFLOW_CTX_DAG_OWNER='***' AIRFLOW_CTX_DAG_ID='my_dag' AIRFLOW_CTX_TASK_ID='accurate' AIRFLOW_CTX_EXECUTION_DATE='2023-10-16T00:00:00+00:00' AIRFLOW_CTX_TRY_NUMBER='1' AIRFLOW_CTX_DAG_RUN_ID='scheduled__2023-10-16T00:00:00+00:00'
[2023-10-17T02:50:00.223+0000] {subprocess.py:63} INFO - Tmp dir root location: /tmp
[2023-10-17T02:50:00.272+0000] {subprocess.py:75} INFO - Running command: ['/bin/bash', '-c', "echo 'accurate"]
[2023-10-17T02:50:00.309+0000] {subprocess.py:86} INFO - Output:
[2023-10-17T02:50:00.322+0000] {subprocess.py:93} INFO - /bin/bash: -c: line 1: unexpected EOF while looking for matching `''
[2023-10-17T02:50:00.331+0000] {subprocess.py:93} INFO - /bin/bash: -c: line 2: syntax error: unexpected end of file
[2023-10-17T02:50:00.339+0000] {subprocess.py:97} INFO - Command exited with return code 2
[2023-10-17T02:50:00.416+0000] {taskinstance.py:1824} ERROR - Task failed with exception
Traceback (most recent call last):
  File "/home/airflow/.local/lib/python3.7/site-packages/airflow/operators/bash.py", line 211, in execute
    f"Bash command failed. The command returned a non-zero exit code {result.exit_code}."
airflow.exceptions.AirflowException: Bash command failed. The command returned a non-zero exit code 2.
[2023-10-17T02:50:00.454+0000] {taskinstance.py:1350} INFO - Marking task as FAILED. dag_id=my_dag, task_id=accurate, execution_date=20231016T000000, start_date=20231017T024957, end_date=20231017T025000
[2023-10-17T02:50:00.580+0000] {standard_task_runner.py:109} ERROR - Failed to execute job 117 for task accurate (Bash command failed. The command returned a non-zero exit code 2.; 106)
[2023-10-17T02:50:00.634+0000] {local_task_job_runner.py:225} INFO - Task exited with return code 1
[2023-10-17T02:50:00.799+0000] {taskinstance.py:2653} INFO - 0 downstream tasks scheduled from follow-on schedule check
