[2023-09-26T03:34:43.934+0000] {taskinstance.py:1103} INFO - Dependencies all met for dep_context=non-requeueable deps ti=<TaskInstance: my_dag.accurate manual__2023-09-26T03:34:23.348858+00:00 [queued]>
[2023-09-26T03:34:43.959+0000] {taskinstance.py:1103} INFO - Dependencies all met for dep_context=requeueable deps ti=<TaskInstance: my_dag.accurate manual__2023-09-26T03:34:23.348858+00:00 [queued]>
[2023-09-26T03:34:43.960+0000] {taskinstance.py:1308} INFO - Starting attempt 1 of 1
[2023-09-26T03:34:44.005+0000] {taskinstance.py:1327} INFO - Executing <Task(BashOperator): accurate> on 2023-09-26 03:34:23.348858+00:00
[2023-09-26T03:34:44.017+0000] {standard_task_runner.py:57} INFO - Started process 261 to run task
[2023-09-26T03:34:44.026+0000] {standard_task_runner.py:84} INFO - Running: ['***', 'tasks', 'run', 'my_dag', 'accurate', 'manual__2023-09-26T03:34:23.348858+00:00', '--job-id', '77', '--raw', '--subdir', 'DAGS_FOLDER/my_dag.py', '--cfg-path', '/tmp/tmpaxs5it3l']
[2023-09-26T03:34:44.031+0000] {standard_task_runner.py:85} INFO - Job 77: Subtask accurate
[2023-09-26T03:34:44.121+0000] {task_command.py:410} INFO - Running <TaskInstance: my_dag.accurate manual__2023-09-26T03:34:23.348858+00:00 [running]> on host b9f7eb4d6527
[2023-09-26T03:34:44.289+0000] {taskinstance.py:1547} INFO - Exporting env vars: AIRFLOW_CTX_DAG_OWNER='***' AIRFLOW_CTX_DAG_ID='my_dag' AIRFLOW_CTX_TASK_ID='accurate' AIRFLOW_CTX_EXECUTION_DATE='2023-09-26T03:34:23.348858+00:00' AIRFLOW_CTX_TRY_NUMBER='1' AIRFLOW_CTX_DAG_RUN_ID='manual__2023-09-26T03:34:23.348858+00:00'
[2023-09-26T03:34:44.293+0000] {subprocess.py:63} INFO - Tmp dir root location: /tmp
[2023-09-26T03:34:44.295+0000] {subprocess.py:75} INFO - Running command: ['/bin/bash', '-c', "echo 'accurate"]
[2023-09-26T03:34:44.315+0000] {subprocess.py:86} INFO - Output:
[2023-09-26T03:34:44.318+0000] {subprocess.py:93} INFO - /bin/bash: -c: line 1: unexpected EOF while looking for matching `''
[2023-09-26T03:34:44.319+0000] {subprocess.py:93} INFO - /bin/bash: -c: line 2: syntax error: unexpected end of file
[2023-09-26T03:34:44.320+0000] {subprocess.py:97} INFO - Command exited with return code 2
[2023-09-26T03:34:44.346+0000] {taskinstance.py:1824} ERROR - Task failed with exception
Traceback (most recent call last):
  File "/home/airflow/.local/lib/python3.7/site-packages/airflow/operators/bash.py", line 211, in execute
    f"Bash command failed. The command returned a non-zero exit code {result.exit_code}."
airflow.exceptions.AirflowException: Bash command failed. The command returned a non-zero exit code 2.
[2023-09-26T03:34:44.355+0000] {taskinstance.py:1350} INFO - Marking task as FAILED. dag_id=my_dag, task_id=accurate, execution_date=20230926T033423, start_date=20230926T033443, end_date=20230926T033444
[2023-09-26T03:34:44.384+0000] {standard_task_runner.py:109} ERROR - Failed to execute job 77 for task accurate (Bash command failed. The command returned a non-zero exit code 2.; 261)
[2023-09-26T03:34:44.439+0000] {local_task_job_runner.py:225} INFO - Task exited with return code 1
[2023-09-26T03:34:44.513+0000] {taskinstance.py:2653} INFO - 0 downstream tasks scheduled from follow-on schedule check
